Workbook

Sheet Dashboard
C1: PORTFOLIO RISK MANAGEMENT
B4: Portfolio Value: | C4: Annualised Return:
B5: 1000000 | C5: =(Returns!H1257/1000000)^(1/5)-1 -> -1
B7: Annualised Volatility: | C7: Sharpe Ratio:
B8: 0.144 | C8: =C5/B8 -> -6.9444444
B10: Maximum Drawdown: | C10: 95% 1-Day VaR:
B11: -0.5037 | C11: 16642.36
B13: 99% 1-Day VaR: | C13: Expected Shortfall:
B14: 28114.05 | C14: 95%: <£24,215.28 99%:<£36,962.57
B18: Portfolio Value:
B38: Drawdown:
B48: Drawdown Chart
B59: Risk Contribution:
B81: Stress Test
B83: Selected Stress Scenario: | C83: Mild Market Downturn
B84: Portfolio Impact | C84: =_xlfn.XLOOKUP(C83,StressTest[[Scenario ]],StressTest[[Portfolio Impact ]]) -> -0.05
B85: Estimated Loss | C85: =_xlfn.XLOOKUP(Dashboard!C83,StressTest[[Scenario ]],StressTest[[£ Impact ]]) -> -50000

Sheet Inputs
A1: Asset | B1: Weight
A2: GOOGL | B2: 0.2
A3: MSFT | B3: 0.2
A4: XOM | B4: 0.2
A5: JPM | B5: 0.2
A6: UNH | B6: 0.2

Sheet Prices
A2: Date | B2: GOOGL | C2: MSFT | D2: XOM | E2: JPM | F2: UNH
A3: Sep 18, 2026 | B3: 349.54 | C3: 493.78 | D3: 163.54 | E3: 349.67 | F3: 376.9
A4: Sep 17, 2026 | B4: 347.33 | C4: 497.75 | D4: 163.27 | E4: 349.31 | F4: 375.21
A5: Sep 16, 2026 | B5: 342.87 | C5: 490.3 | D5: 163.32 | E5: 348.92 | F5: 375.26
A6: Sep 15, 2026 | B6: 344.98 | C6: 497.12 | D6: 169.32 | E6: 352.49 | F6: 375.93
A7: Sep 14, 2026 | B7: 349.39 | C7: 505.41 | D7: 165.08 | E7: 350.13 | F7: 383.55
A8: Sep 11, 2026 | B8: 338.5 | C8: 495.63 | D8: 165.99 | E8: 356.23 | F8: 376.77
A9: Sep 10, 2026 | B9: 332.6 | C9: 492.44 | D9: 165.23 | E9: 353.56 | F9: 385.9
A10: Sep 09, 2026 | B10: 330.65 | C10: 491.65 | D10: 164.23 | E10: 354.71 | F10: 390.65
A11: Sep 08, 2026 | B11: 338.36 | C11: 493.95 | D11: 160.66 | E11: 353.51 | F11: 398.39
A12: Sep 04, 2026 | B12: 338.46 | C12: 499.7 | D12: 159.47 | E12: 358.64 | F12: 394.71
A13: Sep 03, 2026 | B13: 342.26 | C13: 510.12 | D13: 162.21 | E13: 362.06 | F13: 398.49
A14: Sep 02, 2026 | B14: 336.9 | C14: 496.82 | D14: 164.15 | E14: 356.22 | F14: 397.21
... A1257: Sep 20, 2021 | B1257: 137.41 | C1257: 282.45 | D1257: 45.06 | E1257: 134.97 | F1257: 377.04

Sheet Returns
A1: Date | B1: GOOGL | C1: MSFT | D1: XOM | E1: JPM | F1: UNH | G1: Portfolio Return | H1: Portfolio Value | I1: Running High | J1: Drawdown
A2: 44459 | H2: 1000000 | I2: =MAX(I1,H2) -> 1000000 | J2: =(H2-I2)/I2 -> 0
A3: 44460 | B3: =(Prices!B1257/Prices!B1256)-1 -> -0.0022509439 | C3: =(Prices!C1257/Prices!C1256)-1 -> -0.0016965327 | D3: =(Prices!D1257/Prices!D1256)-1 -> 0.000888494 | E3: =(Prices!E1257/Prices!E1256)-1 -> -0.00014815912 | F3: =(Prices!F1257/Prices!F1256)-1 -> 0.00087600542 | G3: =B3*20%+C3*20%+D3*20%+E3*20%+F3*20% -> -0.00046622727 | H3: =H2*(1+G3) -> 999533.77 | I3: =MAX(I2,H3) -> 1000000 | J3: =(H3-I3)/I3 -> -0.00046622727
A4: 44461 | B4: =(Prices!B1256/Prices!B1255)-1 -> -0.0089234312 | C4: =(Prices!C1256/Prices!C1255)-1 -> -0.012667504 | D4: =(Prices!D1256/Prices!D1255)-1 -> -0.028275415 | E4: =(Prices!E1256/Prices!E1255)-1 -> -0.018825411 | F4: =(Prices!F1256/Prices!F1255)-1 -> 0.0088915075 | G4: =B4*20%+C4*20%+D4*20%+E4*20%+F4*20% -> -0.011960051 | H4: =H3*(1+G4) -> 987579.3 | I4: =MAX(I3,H4) -> 1000000 | J4: =(H4-I4)/I4 -> -0.012420702
A5: 44462 | B5: =(Prices!B1255/Prices!B1254)-1 -> -0.0065770661 | C5: =(Prices!C1255/Prices!C1254)-1 -> -0.0032695652 | D5: =(Prices!D1255/Prices!D1254)-1 -> -0.032776618 | E5: =(Prices!E1255/Prices!E1254)-1 -> -0.032693525 | F5: =(Prices!F1255/Prices!F1254)-1 -> 0.001663224 | G5: =B5*20%+C5*20%+D5*20%+E5*20%+F5*20% -> -0.01473071 | H5: =H4*(1+G5) -> 973031.55 | I5: =MAX(I4,H5) -> 1000000 | J5: =(H5-I5)/I5 -> -0.026968446
A6: 44463 | B6: =(Prices!B1254/Prices!B1253)-1 -> -0.0070277561 | C6: =(Prices!C1254/Prices!C1253)-1 -> 0.00073096871 | D6: =(Prices!D1254/Prices!D1253)-1 -> -0.0088971653 | E6: =(Prices!E1254/Prices!E1253)-1 -> -0.01139918 | F6: =(Prices!F1254/Prices!F1253)-1 -> 0.0023123874 | G6: =B6*20%+C6*20%+D6*20%+E6*20%+F6*20% -> -0.004856149 | H6: =H5*(1+G6) -> 968306.37 | I6: =MAX(I5,H6) -> 1000000 | J6: =(H6-I6)/I6 -> -0.031693632
A7: 44466 | B7: =(Prices!B1253/Prices!B1252)-1 -> 0.0080864463 | C7: =(Prices!C1253/Prices!C1252)-1 -> 0.017604137 | D7: =(Prices!D1253/Prices!D1252)-1 -> -0.028933092 | E7: =(Prices!E1253/Prices!E1252)-1 -> -0.023550971 | F7: =(Prices!F1253/Prices!F1252)-1 -> 0.0044834571 | G7: =B7*20%+C7*20%+D7*20%+E7*20%+F7*20% -> -0.0044620044 | H7: =H6*(1+G7) -> 963985.78 | I7: =MAX(I6,H7) -> 1000000 | J7: =(H7-I7)/I7 -> -0.03601422
A8: 44467 | B8: =(Prices!B1252/Prices!B1251)-1 -> 0.038573021 | C8: =(Prices!C1252/Prices!C1251)-1 -> 0.037559721 | D8: =(Prices!D1252/Prices!D1251)-1 -> -0.010340028 | E8: =(Prices!E1252/Prices!E1251)-1 -> 0.0053906517 | F8: =(Prices!F1252/Prices!F1251)-1 -> 0.016667582 | G8: =B8*20%+C8*20%+D8*20%+E8*20%+F8*20% -> 0.01757019 | H8: =H7*(1+G8) -> 980923.19 | I8: =MAX(I7,H8) -> 1000000 | J8: =(H8-I8)/I8 -> -0.019076807
A9: 44468 | B9: =(Prices!B1251/Prices!B1250)-1 -> 0.01097002 | C9: =(Prices!C1251/Prices!C1250)-1 -> -0.0016877018 | D9: =(Prices!D1251/Prices!D1250)-1 -> 0.0007960199 | E9: =(Prices!E1251/Prices!E1250)-1 -> 0.00075116089 | F9: =(Prices!F1251/Prices!F1250)-1 -> -0.0044558651 | G9: =B9*20%+C9*20%+D9*20%+E9*20%+F9*20% -> 0.0012747268 | H9: =H8*(1+G9) -> 982173.6 | I9: =MAX(I8,H9) -> 1000000 | J9: =(H9-I9)/I9 -> -0.017826398
A10: 44469 | B10: =(Prices!B1250/Prices!B1249)-1 -> 0.0050596587 | C10: =(Prices!C1250/Prices!C1249)-1 -> 0.0073548435 | D10: =(Prices!D1250/Prices!D1249)-1 -> 0.018030794 | E10: =(Prices!E1250/Prices!E1249)-1 -> 0.01384658 | F10: =(Prices!F1250/Prices!F1249)-1 -> 0.024735279 | G10: =B10*20%+C10*20%+D10*20%+E10*20%+F10*20% -> 0.013805431 | H10: =H9*(1+G10) -> 995732.93 | I10: =MAX(I9,H10) -> 1000000 | J10: =(H10-I10)/I10 -> -0.0042670677
A11: 44470 | B11: =(Prices!B1249/Prices!B1248)-1 -> -0.020996599 | C11: =(Prices!C1249/Prices!C1248)-1 -> -0.024832408 | D11: =(Prices!D1249/Prices!D1248)-1 -> -0.034617641 | E11: =(Prices!E1249/Prices!E1248)-1 -> -0.020612964 | F11: =(Prices!F1249/Prices!F1248)-1 -> -0.0042954368 | G11: =B11*20%+C11*20%+D11*20%+E11*20%+F11*20% -> -0.02107101 | H11: =H10*(1+G11) -> 974751.83 | I11: =MAX(I10,H11) -> 1000000 | J11: =(H11-I11)/I11 -> -0.025248166
A12: 44473 | B12: =(Prices!B1248/Prices!B1247)-1 -> 0.021601208 | C12: =(Prices!C1248/Prices!C1247)-1 -> 0.021162269 | D12: =(Prices!D1248/Prices!D1247)-1 -> -0.012934363 | E12: =(Prices!E1248/Prices!E1247)-1 -> 0.0010860711 | F12: =(Prices!F1248/Prices!F1247)-1 -> 0.014000057 | G12: =B12*20%+C12*20%+D12*20%+E12*20%+F12*20% -> 0.0089830484 | H12: =H11*(1+G12) -> 983508.08 | I12: =MAX(I11,H12) -> 1000000 | J12: =(H12-I12)/I12 -> -0.016491923
A13: 44474 | B13: =(Prices!B1247/Prices!B1246)-1 -> -0.01736678 | C13: =(Prices!C1247/Prices!C1246)-1 -> -0.019557608 | D13: =(Prices!D1247/Prices!D1246)-1 -> 0.0017404757 | E13: =(Prices!E1247/Prices!E1246)-1 -> -0.016029923 | F13: =(Prices!F1247/Prices!F1246)-1 -> -0.016330959 | G13: =B13*20%+C13*20%+D13*20%+E13*20%+F13*20% -> -0.013508959 | H13: =H12*(1+G13) -> 970221.91 | I13: =MAX(I12,H13) -> 1000000 | J13: =(H13-I13)/I13 -> -0.029778094
A14: 44475 | B14: =(Prices!B1246/Prices!B1245)-1 -> -0.01122771 | C14: =(Prices!C1246/Prices!C1245)-1 -> -0.014859052 | D14: =(Prices!D1246/Prices!D1245)-1 -> 0.018715524 | E14: =(Prices!E1246/Prices!E1245)-1 -> -0.0021327646 | F14: =(Prices!F1246/Prices!F1245)-1 -> -0.0020822344 | G14: =B14*20%+C14*20%+D14*20%+E14*20%+F14*20% -> -0.0023172474 | H14: =H13*(1+G14) -> 967973.66 | I14: =MAX(I13,H14) -> 1000000 | J14: =(H14-I14)/I14 -> -0.032026338
A15: 44476 | B15: =(Prices!B1245/Prices!B1244)-1 -> -0.011891814 | C15: =(Prices!C1245/Prices!C1244)-1 -> -0.0059014771 | D15: =(Prices!D1245/Prices!D1244)-1 -> -0.002946376 | E15: =(Prices!E1245/Prices!E1244)-1 -> -0.0062918074 | F15: =(Prices!F1245/Prices!F1244)-1 -> -0.025802613 | G15: =B15*20%+C15*20%+D15*20%+E15*20%+F15*20% -> -0.010566817 | H15: =H14*(1+G15) -> 957745.26 | I15: =MAX(I14,H15) -> 1000000 | J15: =(H15-I15)/I15 -> -0.042254739
A16: 44477 | B16: =(Prices!B1244/Prices!B1243)-1 -> -0.0040441973 | C16: =(Prices!C1244/Prices!C1243)-1 -> 0 | D16: =(Prices!D1244/Prices!D1243)-1 -> -0.024338827 | E16: =(Prices!E1244/Prices!E1243)-1 -> -0.00079412349 | F16: =(Prices!F1244/Prices!F1243)-1 -> -0.0092183187 | G16: =B16*20%+C16*20%+D16*20%+E16*20%+F16*20% -> -0.0076790933 | H16: =H15*(1+G16) -> 950390.65 | I16: =MAX(I15,H16) -> 1000000 | J16: =(H16-I16)/I16 -> -0.049609354
A17: 44480 | B17: =(Prices!B1243/Prices!B1242)-1 -> 0.0063226744 | C17: =(Prices!C1243/Prices!C1242)-1 -> 0.0021247964 | D17: =(Prices!D1243/Prices!D1242)-1 -> 0.010065815 | E17: =(Prices!E1243/Prices!E1242)-1 -> 0.021496654 | F17: =(Prices!F1243/Prices!F1242)-1 -> 0.0085675676 | G17: =B17*20%+C17*20%+D17*20%+E17*20%+F17*20% -> 0.0097155014 | H17: =H16*(1+G17) -> 959624.17 | I17: =MAX(I16,H17) -> 1000000 | J17: =(H17-I17)/I17 -> -0.040375832
A18: 44481 | B18: =(Prices!B1242/Prices!B1241)-1 -> 0.018052678 | C18: =(Prices!C1242/Prices!C1241)-1 -> 0.0046250178 | D18: =(Prices!D1242/Prices!D1241)-1 -> 0.0052539405 | E18: =(Prices!E1242/Prices!E1241)-1 -> 0.0077661966 | F18: =(Prices!F1242/Prices!F1241)-1 -> 0.0043431053 | G18: =B18*20%+C18*20%+D18*20%+E18*20%+F18*20% -> 0.0080081877 | H18: =H17*(1+G18) -> 967309.02 | I18: =MAX(I17,H18) -> 1000000 | J18: =(H18-I18)/I18 -> -0.032690982
A19: 44482 | B19: =(Prices!B1241/Prices!B1240)-1 -> -0.0082911439 | C19: =(Prices!C1241/Prices!C1240)-1 -> -0.011604192 | D19: =(Prices!D1241/Prices!D1240)-1 -> 0.0027317073 | E19: =(Prices!E1241/Prices!E1240)-1 -> 0.027078086 | F19: =(Prices!F1241/Prices!F1240)-1 -> -0.0007594662 | G19: =B19*20%+C19*20%+D19*20%+E19*20%+F19*20% -> 0.0018309983 | H19: =H18*(1+G19) -> 969080.16 | I19: =MAX(I18,H19) -> 1000000 | J19: =(H19-I19)/I19 -> -0.030919841
A20: 44483 | B20: =(Prices!B1240/Prices!B1239)-1 -> -0.025246746 | C20: =(Prices!C1240/Prices!C1239)-1 -> -0.021269273 | D20: =(Prices!D1240/Prices!D1239)-1 -> -0.014991351 | E20: =(Prices!E1240/Prices!E1239)-1 -> -0.015159868 | F20: =(Prices!F1240/Prices!F1239)-1 -> -0.039995834 | G20: =B20*20%+C20*20%+D20*20%+E20*20%+F20*20% -> -0.023332614 | H20: =H19*(1+G20) -> 946468.99 | I20: =MAX(I19,H20) -> 1000000 | J20: =(H20-I20)/I20 -> -0.053531014
A21: 44484 | B21: =(Prices!B1239/Prices!B1238)-1 -> -0.0015709797 | C21: =(Prices!C1239/Prices!C1238)-1 -> -0.0047951774 | D21: =(Prices!D1239/Prices!D1238)-1 -> -0.0095183705 | E21: =(Prices!E1239/Prices!E1238)-1 -> -0.018796484 | F21: =(Prices!F1239/Prices!F1238)-1 -> -0.018001432 | G21: =B21*20%+C21*20%+D21*20%+E21*20%+F21*20% -> -0.010536489 | H21: =H20*(1+G21) -> 936496.53 | I21: =MAX(I20,H21) -> 1000000 | J21: =(H21-I21)/I21 -> -0.063503474
A22: 44487 | B22: =(Prices!B1238/Prices!B1237)-1 -> -0.0098281836 | C22: =(Prices!C1238/Prices!C1237)-1 -> -0.010003052 | D22: =(Prices!D1238/Prices!D1237)-1 -> 0.00057142857 | E22: =(Prices!E1238/Prices!E1237)-1 -> 0.00033818059 | F22: =(Prices!F1238/Prices!F1237)-1 -> 0.0081200217 | G22: =B22*20%+C22*20%+D22*20%+E22*20%+F22*20% -> -0.0021603209 | H22: =H21*(1+G22) -> 934473.39 | I22: =MAX(I21,H22) -> 1000000 | J22: =(H22-I22)/I22 -> -0.065526607
A23: 44488 | B23: =(Prices!B1237/Prices!B1236)-1 -> -0.003241948 | C23: =(Prices!C1237/Prices!C1236)-1 -> -0.003076195 | D23: =(Prices!D1237/Prices!D1236)-1 -> -0.014824545 | E23: =(Prices!E1237/Prices!E1236)-1 -> -0.011962042 | F23: =(Prices!F1237/Prices!F1236)-1 -> 0.00056743442 | G23: =B23*20%+C23*20%+D23*20%+E23*20%+F23*20% -> -0.0065074591 | H23: =H22*(1+G23) -> 928392.35 | I23: =MAX(I22,H23) -> 1000000 | J23: =(H23-I23)/I23 -> -0.071607655
A24: 44489 | B24: =(Prices!B1236/Prices!B1235)-1 -> 0.010396639 | C24: =(Prices!C1236/Prices!C1235)-1 -> 0.0026776938 | D24: =(Prices!D1236/Prices!D1235)-1 -> -0.0054124673 | E24: =(Prices!E1236/Prices!E1235)-1 -> -0.013319267 | F24: =(Prices!F1236/Prices!F1235)-1 -> -0.024628931 | G24: =B24*20%+C24*20%+D24*20%+E24*20%+F24*20% -> -0.0060572664 | H24: =H23*(1+G24) -> 922768.83 | I24: =MAX(I23,H24) -> 1000000 | J24: =(H24-I24)/I24 -> -0.077231174
A25: 44490 | B25: =(Prices!B1235/Prices!B1234)-1 -> -0.00085378869 | C25: =(Prices!C1235/Prices!C1234)-1 -> -0.010763144 | D25: =(Prices!D1235/Prices!D1234)-1 -> 0.018437559 | E25: =(Prices!E1235/Prices!E1234)-1 -> 0.0079085532 | F25: =(Prices!F1235/Prices!F1234)-1 -> -0.016259559 | G25: =B25*20%+C25*20%+D25*20%+E25*20%+F25*20% -> -0.00030607577 | H25: =H24*(1+G25) -> 922486.39 | I25: =MAX(I24,H25) -> 1000000 | J25: =(H25-I25)/I25 -> -0.077513612
A26: 44491 | B26: =(Prices!B1234/Prices!B1233)-1 -> 0.031408234 | C26: =(Prices!C1234/Prices!C1233)-1 -> 0.0051565502 | D26: =(Prices!D1234/Prices!D1233)-1 -> -0.0067962998 | E26: =(Prices!E1234/Prices!E1233)-1 -> -0.01324677 | F26: =(Prices!F1234/Prices!F1233)-1 -> -0.015304009 | G26: =B26*20%+C26*20%+D26*20%+E26*20%+F26*20% -> 0.000243541 | H26: =H25*(1+G26) -> 922711.05 | I26: =MAX(I25,H26) -> 1000000 | J26: =(H26-I26)/I26 -> -0.077288948
A27: 44494 | B27: =(Prices!B1233/Prices!B1232)-1 -> 0.00088138083 | C27: =(Prices!C1233/Prices!C1232)-1 -> 0.0033477614 | D27: =(Prices!D1233/Prices!D1232)-1 -> -0.019074074 | E27: =(Prices!E1233/Prices!E1232)-1 -> 0.0048764415 | F27: =(Prices!F1233/Prices!F1232)-1 -> -0.00073054913 | G27: =B27*20%+C27*20%+D27*20%+E27*20%+F27*20% -> -0.0021398079 | H27: =H26*(1+G27) -> 920736.63 | I27: =MAX(I26,H27) -> 1000000 | J27: =(H27-I27)/I27 -> -0.079263373
A28: 44495 | B28: =(Prices!B1232/Prices!B1231)-1 -> -0.013405797 | C28: =(Prices!C1232/Prices!C1231)-1 -> -0.0063839796 | D28: =(Prices!D1232/Prices!D1231)-1 -> -0.022624434 | E28: =(Prices!E1232/Prices!E1231)-1 -> -0.0026945321 | F28: =(Prices!F1232/Prices!F1231)-1 -> -0.011339561 | G28: =B28*20%+C28*20%+D28*20%+E28*20%+F28*20% -> -0.011289661 | H28: =H27*(1+G28) -> 910341.82 | I28: =MAX(I27,H28) -> 1000000 | J28: =(H28-I28)/I28 -> -0.089658177
A29: 44496 | B29: =(Prices!B1231/Prices!B1230)-1 -> -0.047224524 | C29: =(Prices!C1231/Prices!C1230)-1 -> -0.040430745 | D29: =(Prices!D1231/Prices!D1230)-1 -> 0.026570048 | E29: =(Prices!E1231/Prices!E1230)-1 -> 0.021276596 | F29: =(Prices!F1231/Prices!F1230)-1 -> 0.0025585325 | G29: =B29*20%+C29*20%+D29*20%+E29*20%+F29*20% -> -0.0074500185 | H29: =H28*(1+G29) -> 903559.76 | I29: =MAX(I28,H29) -> 1000000 | J29: =(H29-I29)/I29 -> -0.09644024
A30: 44497 | B30: =(Prices!B1230/Prices!B1229)-1 -> 0.0025610853 | C30: =(Prices!C1230/Prices!C1229)-1 -> -0.0036300556 | D30: =(Prices!D1230/Prices!D1229)-1 -> -0.0027793218 | E30: =(Prices!E1230/Prices!E1229)-1 -> -0.014811876 | F30: =(Prices!F1230/Prices!F1229)-1 -> -0.0043019539 | G30: =B30*20%+C30*20%+D30*20%+E30*20%+F30*20% -> -0.0045924244 | H30: =H29*(1+G30) -> 899410.23 | I30: =MAX(I29,H30) -> 1000000 | J30: =(H30-I30)/I30 -> -0.10058977
A31: 44498 | B31: =(Prices!B1229/Prices!B1228)-1 -> -0.014865326 | C31: =(Prices!C1229/Prices!C1228)-1 -> -0.021900333 | D31: =(Prices!D1229/Prices!D1228)-1 -> -0.0024029575 | E31: =(Prices!E1229/Prices!E1228)-1 -> 0.0027184724 | F31: =(Prices!F1229/Prices!F1228)-1 -> -0.010910906 | G31: =B31*20%+C31*20%+D31*20%+E31*20%+F31*20% -> -0.00947221 | H31: =H30*(1+G31) -> 890890.83 | I31: =MAX(I30,H31) -> 1000000 | J31: =(H31-I31)/I31 -> -0.10910917
A32: 44501 | B32: =(Prices!B1228/Prices!B1227)-1 -> 0.031729281 | C32: =(Prices!C1228/Prices!C1227)-1 -> 0.0068014299 | D32: =(Prices!D1228/Prices!D1227)-1 -> -0.017792302 | E32: =(Prices!E1228/Prices!E1227)-1 -> 0.00053071514 | F32: =(Prices!F1228/Prices!F1227)-1 -> 0.014004387 | G32: =B32*20%+C32*20%+D32*20%+E32*20%+F32*20% -> 0.0070547022 | H32: =H31*(1+G32) -> 897175.8 | I32: =MAX(I31,H32) -> 1000000 | J32: =(H32-I32)/I32 -> -0.1028242
A33: 44502 | B33: =(Prices!B1227/Prices!B1226)-1 -> -0.01332778 | C33: =(Prices!C1227/Prices!C1226)-1 -> -0.011260205 | D33: =(Prices!D1227/Prices!D1226)-1 -> 0.0125 | E33: =(Prices!E1227/Prices!E1226)-1 -> -0.0038987643 | F33: =(Prices!F1227/Prices!F1226)-1 -> 0.0045764928 | G33: =B33*20%+C33*20%+D33*20%+E33*20%+F33*20% -> -0.0022820512 | H33: =H32*(1+G33) -> 895128.4 | I33: =MAX(I32,H33) -> 1000000 | J33: =(H33-I33)/I33 -> -0.1048716
A34: 44503 | B34: =(Prices!B1226/Prices!B1225)-1 -> -0.0079878805 | C34: =(Prices!C1226/Prices!C1225)-1 -> -0.002620496 | D34: =(Prices!D1226/Prices!D1225)-1 -> 0.013979497 | E34: =(Prices!E1226/Prices!E1225)-1 -> -0.00033029462 | F34: =(Prices!F1226/Prices!F1225)-1 -> -0.011560279 | G34: =B34*20%+C34*20%+D34*20%+E34*20%+F34*20% -> -0.0017038906 | H34: =H33*(1+G34) -> 893603.19 | I34: =MAX(I33,H34) -> 1000000 | J34: =(H34-I34)/I34 -> -0.10639681
A35: 44504 | B35: =(Prices!B1225/Prices!B1224)-1 -> -0.011234425 | C35: =(Prices!C1225/Prices!C1224)-1 -> -0.0072470501 | D35: =(Prices!D1225/Prices!D1224)-1 -> -0.007400555 | E35: =(Prices!E1225/Prices!E1224)-1 -> 0.013253012 | F35: =(Prices!F1225/Prices!F1224)-1 -> 0.0012461358 | G35: =B35*20%+C35*20%+D35*20%+E35*20%+F35*20% -> -0.0022765765 | H35: =H34*(1+G35) -> 891568.84 | I35: =MAX(I34,H35) -> 1000000 | J35: =(H35-I35)/I35 -> -0.10843116
A36: 44505 | B36: =(Prices!B1224/Prices!B1223)-1 -> -0.0039335368 | C36: =(Prices!C1224/Prices!C1223)-1 -> 0.0011161752 | D36: =(Prices!D1224/Prices!D1223)-1 -> -0.0095290453 | E36: =(Prices!E1224/Prices!E1223)-1 -> 0.0014747285 | F36: =(Prices!F1224/Prices!F1223)-1 -> 0.002065173 | G36: =B36*20%+C36*20%+D36*20%+E36*20%+F36*20% -> -0.0017613011 | H36: =H35*(1+G36) -> 889998.52 | I36: =MAX(I35,H36) -> 1000000 | J36: =(H36-I36)/I36 -> -0.11000148
A37: 44508 | B37: =(Prices!B1223/Prices!B1222)-1 -> -0.0012192644 | C37: =(Prices!C1223/Prices!C1222)-1 -> -0.0027518397 | D37: =(Prices!D1223/Prices!D1222)-1 -> -0.010516772 | E37: =(Prices!E1223/Prices!E1222)-1 -> -0.0059968017 | F37: =(Prices!F1223/Prices!F1222)-1 -> -0.014716669 | G37: =B37*20%+C37*20%+D37*20%+E37*20%+F37*20% -> -0.0070402694 | H37: =H36*(1+G37) -> 883732.69 | I37: =MAX(I36,H37) -> 1000000 | J37: =(H37-I37)/I37 -> -0.11626731
A38: 44509 | B38: =(Prices!B1222/Prices!B1221)-1 -> 0.00081350417 | C38: =(Prices!C1222/Prices!C1221)-1 -> 0.0031015446 | D38: =(Prices!D1222/Prices!D1221)-1 -> -0.0096965344 | E38: =(Prices!E1222/Prices!E1221)-1 -> 0.0076540889 | F38: =(Prices!F1222/Prices!F1221)-1 -> -0.0037243948 | G38: =B38*20%+C38*20%+D38*20%+E38*20%+F38*20% -> -0.00037035831 | H38: =H37*(1+G38) -> 883405.39 | I38: =MAX(I37,H38) -> 1000000 | J38: =(H38-I38)/I38 -> -0.11659461
A39: 44510 | B39: =(Prices!B1221/Prices!B1220)-1 -> 0.020689178 | C39: =(Prices!C1221/Prices!C1220)-1 -> 0.015560035 | D39: =(Prices!D1221/Prices!D1220)-1 -> 0.020150211 | E39: =(Prices!E1221/Prices!E1220)-1 -> 0.00094086022 | F39: =(Prices!F1221/Prices!F1220)-1 -> 0.009686786 | G39: =B39*20%+C39*20%+D39*20%+E39*20%+F39*20% -> 0.013405414 | H39: =H38*(1+G39) -> 895247.81 | I39: =MAX(I38,H39) -> 1000000 | J39: =(H39-I39)/I39 -> -0.10475219
A40: 44511 | B40: =(Prices!B1220/Prices!B1219)-1 -> 0.00090033936 | C40: =(Prices!C1220/Prices!C1219)-1 -> -0.004889669 | D40: =(Prices!D1220/Prices!D1219)-1 -> -0.0020109689 | E40: =(Prices!E1220/Prices!E1219)-1 -> 6.7208818e-05 | F40: =(Prices!F1220/Prices!F1219)-1 -> 0.0054801733 | G40: =B40*20%+C40*20%+D40*20%+E40*20%+F40*20% -> -9.0583298e-05 | H40: =H39*(1+G40) -> 895166.71 | I40: =MAX(I39,H40) -> 1000000 | J40: =(H40-I40)/I40 -> -0.10483329
...

Sheet Risk Analysis
B1: ANNUALISED VOLATILITY | E1: CORROLATION MATRIX | L1: COVARIANCE MATRIX | S1: WEIGHTS
B2: Asset | C2: Annualised Volatility | E2: Column1 | F2: GOOGL | G2: MSFT | H2: XOM | I2: JPM | J2: UNH | L2: Column1 | M2: GOOGL | N2: MSFT | O2: XOM | P2: JPM | Q2: UNH | S2: Stock | T2: Weight
B3: GOOGL | C3: =_xlfn.STDEV.S(Returns!B3:B1256)*SQRT(252) -> 0.32111573 | E3: GOOGL | F3: 1 | G3: =CORREL(Returns!B3:B1256,Returns!C3:C1256) -> 0.55214559 | H3: =CORREL(Returns!B3:B1256,Returns!D3:D1256) -> 0.035548313 | I3: =CORREL(Returns!B3:B1256,Returns!E3:E1256) -> 0.31264894 | J3: =CORREL(Returns!B3:B1256,Returns!F3:F1256) -> 0.10155408 | L3: GOOGL | M3: =N3 -> 0.00019705522 | N3: =_xlfn.COVARIANCE.S(Returns!B3:B1256,Returns!C3:C1256) -> 0.00019705522 | O3: =_xlfn.COVARIANCE.S(Returns!B3:B1256,Returns!D3:D1256) -> 1.2106401e-05 | P3: =_xlfn.COVARIANCE.S(Returns!B3:B1256,Returns!E3:E1256) -> 9.7053915e-05 | Q3: =_xlfn.COVARIANCE.S(Returns!B3:B1256,Returns!F3:F1256) -> 4.4242778e-05 | S3: GOOGL | T3: 0.2
B4: MSFT | C4: =_xlfn.STDEV.S(Returns!C3:C1256)*SQRT(252) -> 0.28007433 | E4: MSFT | F4: =CORREL(Returns!C3:C1256,Returns!B3:B1256) -> 0.55214559 | G4: 1 | H4: 0.05 | I4: =CORREL(Returns!C3:C1256,Returns!E3:E1256) -> 0.29593631 | J4: =CORREL(Returns!C3:C1256,Returns!F3:F1256) -> 0.11417183 | L4: MSFT | M4: =_xlfn.COVARIANCE.S(Returns!B3:B1256,Returns!C3:C1256) -> 0.00019705522 | N4: =_xlfn.COVARIANCE.S(Returns!C3:C1256,Returns!C3:C1256) -> 0.00031127632 | O4: =_xlfn.COVARIANCE.S(Returns!C3:C1256,Returns!D3:D1256) -> 1.444745e-05 | P4: =_xlfn.COVARIANCE.S(Returns!C3:C1256,Returns!E3:E1256) -> 8.0124638e-05 | Q4: =_xlfn.COVARIANCE.S(Returns!C3:C1256,Returns!F3:F1256) -> 4.3382615e-05 | S4: MSFT | T4: 0.2
B5: XOM | C5: =_xlfn.STDEV.S(Returns!D3:D1256)*SQRT(252) -> 0.26726066 | E5: XOM | F5: 0.04 | G5: =CORREL(Returns!C3:C1256,Returns!D3:D1256) -> 0.048638862 | H5: 1 | I5: =CORREL(Returns!D3:D1256,Returns!E3:E1256) -> 0.27041328 | J5: =CORREL(Returns!D3:D1256,Returns!F3:F1256) -> 0.068577959 | L5: XOM | M5: =_xlfn.COVARIANCE.S(Returns!B3:B1256,Returns!D3:D1256) -> 1.2106401e-05 | N5: =_xlfn.COVARIANCE.S(Returns!C3:C1256,Returns!D3:D1256) -> 1.444745e-05 | O5: =_xlfn.COVARIANCE.S(Returns!D3:D1256,Returns!D3:D1256) -> 0.00028344547 | P5: =_xlfn.COVARIANCE.S(Returns!D3:D1256,Returns!E3:E1256) -> 6.9864661e-05 | Q5: =_xlfn.COVARIANCE.S(Returns!D3:D1256,Returns!F3:F1256) -> 2.4865834e-05 | S5: XOM | T5: 0.2
B6: JPM | C6: =_xlfn.STDEV.S(Returns!E3:E1256)*SQRT(252) -> 0.24360997 | E6: JPM | F6: 0.31 | G6: 0.3 | H6: 0,27 | I6: 1 | J6: =CORREL(Returns!E3:E1256,Returns!F3:F1256) -> 0.15155143 | L6: JPM | M6: =_xlfn.COVARIANCE.S(Returns!B3:B1256,Returns!E3:E1256) -> 9.7053915e-05 | N6: =_xlfn.COVARIANCE.S(Returns!C3:C1256,Returns!E3:E1256) -> 8.0124638e-05 | O6: =_xlfn.COVARIANCE.S(Returns!D3:D1256,Returns!E3:E1256) -> 6.9864661e-05 | P6: 0 | Q6: =_xlfn.COVARIANCE.S(Returns!E3:E1256,Returns!F3:F1256) -> 5.0088558e-05 | S6: JPM | T6: 0.2
B7: UNH | C7: =_xlfn.STDEV.S(Returns!F3:F1256)*SQRT(252) -> 0.3418881 | E7: UNH | F7: 0.1 | G7: 0.11 | H7: 0.07 | I7: 0.15 | J7: 1 | L7: UNH | M7: =_xlfn.COVARIANCE.S(Returns!B3:B1256,Returns!F3:F1256) -> 4.4242778e-05 | N7: =_xlfn.COVARIANCE.S(Returns!C3:C1256,Returns!F3:F1256) -> 4.3382615e-05 | O7: =_xlfn.COVARIANCE.S(Returns!D3:D1256,Returns!F3:F1256) -> 2.4865834e-05 | P7: =_xlfn.COVARIANCE.S(Returns!E3:E1256,Returns!F3:F1256) -> 5.0088558e-05 | Q7: 0 | S7: UNH | T7: 0.2
B9: PORFTOLIO RISK ANALYSIS | E9: Column1 | F9: 95% | G9: 99% | I9: Asset | J9: Weight | K9: Risk Contribution | L9: Workings
B10: Daily Portfolio Volitility: | C10: =SQRT(SUMPRODUCT(T3:T7,MMULT(M3:Q7,T3:T7))) -> 0.0090735686 | E10: Historic VaR | F10: =-_xlfn.PERCENTILE.INC(Returns!G3:G1256,0.05)*1000000 -> 16642.36 | G10: =-_xlfn.PERCENTILE.INC(Returns!G3:G1256,0.01)*1000000 -> 28114.055 | I10: GOOGL | J10: 0.2 | K10: =L10/SUM($L$10:$L$14) -> 0.26601039 | L10: =J10*(M3*$J$10+N3*$J$11+O3*$J$12+P3*$J$13+Q3*$J$14) -> 2.1900542e-05
B11: Annualised Portfolio Volatility: | C11: =C10*SQRT(252) -> 0.14403844 | E11: Parametric VaR | F11: =1.645*C10*1000000 -> 14926.02 | G11: =2.326*C10*1000000 -> 21105.12 | I11: MSFT | J11: 0.2 | K11: =L11/SUM($L$10:$L$14) -> 0.31399928 | L11: =J11*(M4*$J$10+N4*$J$11+O4*$J$12+P4*$J$13+Q4*$J$14) -> 2.585145e-05
B12: Maximum Drawdown | C12: =MIN(Returns!J2:J1255) -> -0.50372573 | E12: Expected Shortfall | F12: =-AVERAGEIF(Returns!G3:G1256,"<"&_xlfn.PERCENTILE.INC(Returns!G3:G1256,0.05),Returns!G3:G1256)*1000000 -> 24215.283 | G12: =-AVERAGEIF(Returns!G3:G1256,"<"&_xlfn.PERCENTILE.INC(Returns!G3:G1256,0.01),Returns!G3:G1256)*1000000 -> 36962.571 | I12: XOM | J12: 0.2 | K12: =L12/SUM($L$10:$L$14) -> 0.19663868 | L12: =J12*(M5*$J$10+N5*$J$11+O5*$J$12+P5*$J$13+Q5*$J$14) -> 1.6189193e-05
I13: JPM | J13: 0.2 | K13: =L13/SUM($L$10:$L$14) -> 0.14436198 | L13: =J13*(M6*$J$10+N6*$J$11+O6*$J$12+P6*$J$13+Q6*$J$14) -> 1.1885271e-05
I14: UNH | J14: 0.2 | K14: =L14/SUM($L$10:$L$14) -> 0.078989668 | L14: =J14*(M7*$J$10+N7*$J$11+O7*$J$12+P7*$J$13+Q7*$J$14) -> 6.5031914e-06
I15: Total | J15: 1 | K15: 1

Sheet Stress Tests
B2: Scenario | C2: GOOGL | D2: MSFT | E2: XOM | F2: JPM | G2: UNH | H2: Portfolio Impact | I2: £ Impact
B3: Mild Market Downturn | C3: -0.05 | D3: -0.05 | E3: -0.05 | F3: -0.05 | G3: -0.05 | H3: =SUM(C3:G3)*20% -> -0.05 | I3: =H3*1000000 -> -50000
B4: Market Correction | C4: -0.1 | D4: -0.1 | E4: -0.1 | F4: -0.1 | G4: -0.1 | H4: =SUM(C4:G4)*20% -> -0.1 | I4: =H4*1000000 -> -100000
B5: Severe Market Shock | C5: -0.2 | D5: -0.2 | E5: -0.2 | F5: -0.2 | G5: -0.2 | H5: =SUM(C5:G5)*20% -> -0.2 | I5: =H5*1000000 -> -200000
B6: Tech Shock | C6: -0.25 | D6: -0.2 | E6: -0.05 | F6: -0.05 | G6: -0.05 | H6: =SUM(C6:G6)*20% -> -0.12 | I6: =H6*1000000 -> -120000
B7: Energy Shock | C7: -0.05 | D7: -0.05 | E7: -0.3 | F7: -0.05 | G7: -0.05 | H7: =SUM(C7:G7)*20% -> -0.1 | I7: =H7*1000000 -> -100000
B8: Financial Shock | C8: -0.05 | D8: -0.05 | E8: -0.05 | F8: -0.3 | G8: -0.05 | H8: =SUM(C8:G8)*20% -> -0.1 | I8: =H8*1000000 -> -100000
